Workbook
Name PMAT: '[1]LISTA PRECIOS'!$B$3:$F$355

Sheet Mat. Electricos
C3: PEDIDO DE PRESUPUESTO MATERIALES VIVIENDA MT | M3: Bastidor | N3: tapa | O3: modulo 10A | P3: modulo 20 A
C4: Cajas rectangulares PVC | E4: =+K5+K6+K18+K25+K32+2 -> 33 | J4: Tomas 2 circ.
C5: Cajas octogonal PVC | E5: =+K41 -> 22 | J5: Cajas rectangulares C1 | K5: 12 | M5: =+K5 -> 12 | N5: =12+50 -> 62 | O5: =6+M53-P5 -> 42 | P5: =1+2 -> 3
C6: Cajas de 20x20 PVC | E6: 3 | J6: Cajas rectangulares C2 | K6: 8 | M6: =+K6 -> 8
C7: Caja 10x10 | E7: 5 | J7: Cano corrugado de 19-20 mm (3/4")
C8: Tablero 24bocas de embutir PVC | E8: 1 | I8: C1 | J8: 2x4 mm + N | K8: 35 | L8: ml cada color
C9: CABLES | I9: C1 | J9: TM 20 A | K9: 35 | L9: ml
C10: Cable 4 mm | E10: =+K8*2 -> 70 | I10: C2 | J10: 2x2.5 mm + N | K10: 22.3
C11: Cable Tierra 4 mm | E11: =+E10/2 -> 35
C12: Cable 2.5 mm | E12: =1000-350 -> 650
C13: Cable tierra 2,5 | E13: 350 | J13: bornera para 6 ramales capacidad 20 A | K13: 1
C14: Cable 1.5 mm | E14: 550 | I14: C2 | J14: TM 20 A
C15: Cable tierra 1,5 | E15: =+E14/2 -> 275
C16: Cable Sintenax de 3x16 mm | E16: 25
C17: Cable Tierra 16 mm | E17: 10 | J17: Lavarropa
C18: Caño rigido 1" | E18: 12 | J18: Cajas rectangulares | K18: 2 | M18: =+K18 -> 2
C19: Curva PVC rigida 1" | E19: 6
C20: Union PVC rigido 1" | E20: 6 | J20: Cano corrugado de 19-20 mm (3/4") | K20: 10
C21: Caño corrugado 3/4 x 25mts | E21: 520 | J21: 2x2.5 mm + N | K21: 11.5
C22: Caño corrugado 7/8 x 25mts | E22: 50 | I22: C3 | J22: TM 20 A | K22: 1
C23: Conectores 3/4 | E23: =+(E4+E5)*2+10*2-E24 -> 104
C24: Conectores 7/8 | E24: =+K5*2+2 -> 26 | J24: Tomas 20A Cocina
C25: Grapas U de fijacion de PVC | E25: 100 | J25: Cajas rectangulares | K25: 6 | L25: u | M25: =+K25 -> 6
C26: 2 bolsas Precintos 20cm de largo | E26: 2 | J26: Cano corrugado de 19-20 mm (3/4") | K26: 48.1 | L26: ml
C27: Cinta Aisladora grande | E27: 4 | J27: 2x2.5 mm + N | K27: 18.2 | L27: ml cada color
C28: Disyuntor de 2x63 A | E28: 1 | I28: C4 cocina 2 tomas | J28: TM 20 A | K28: 7
C29: Termica 2x63 A | E29: 1 | I29: C5 cocina 4 tomas | J29: TM 10 A | K29: 7
C30: Termica 2x10 A | E30: =1+1+1+2 -> 5
C31: Termica 2x16 A | E31: 1 | J31: Aire Acondicionado
C32: Termica 2x20 A | E32: =2+1+1 -> 4 | J32: Cajas rectangulares | K32: 3 | L32: u | M32: =+K32 -> 3
C33: Bornera DIN puesta a tierra cable 16 mm | E33: 2 | J33: Cano corrugado de 19-20 mm (3/4") | K33: 48.1
C34: Ojos de buey din | E34: 2 | J34: 2x2.5 mm + N | K34: 48.1 | L34: ml cada color
C35: Jabalina completa 1.5 m para cable 16 mm | E35: 1 | I35: C6 Dorm | J35: TM 10 A | K35: 12 | L35: ml
C36: Bastidor + tapa Jeluz Verona | E36: =+M53 -> 39 | I36: C7 Estudio | J36: TM 10 A | K36: 8 | L36: ml
C37: Tapon Jeluz Verona | E37: =+N53 -> 78
C38: Modulos toma 220 v 10 A | E38: =+O53 -> 42 | I38: C8 Living | J38: TM 16 A | K38: 17 | L38: ml
C39: Modulos toma 220 v 20 A | E39: =+P53 -> 3
C40: Modulo Internet | E40: 2 | J40: Illuminacion 2 Ciruitos
C41: Modulo llava de un punto | E41: 8 | J41: Cajas oct. 22 | K41: 22 | L41: u
C42: Portalampara y Lamparas led 12 w | E42: =+K41 -> 22 | J42: Cano corrugado de 19-20 mm (3/4") | K42: 55.9 | L42: ml
...

Sheet Mat. Sanit.
B3: PEDIDO DE MATERIALES SANITARIOS OBRA MT
B4: DESCRIPCION | C4: DESCRIPCION | D4: UNIDAD | E4: CANTIDAD
B5: DESAGUES
B6: Tubo Awaduct M-H | C6: 40mm | D6: Metros | E6: 1.5
B7: Tubo Awaduct M-H | C7: 50mm | D7: Metros | E7: 5
B8: Tubo Awaduct M-H | C8: 110mm | D8: Metros | E8: 4
B9: Codo 45º | C9: 40 MH | D9: Unidades | E9: 1
B10: Codo 45º | C10: 50 MH | D10: Unidades | E10: 2
B11: Codo 45º | C11: 63 MH | D11: Unidades | E11: 2
B12: Codo 45º | C12: 110 MH | D12: Unidades | E12: 1
B13: Cupla | C13: 50 HH | D13: Unidades | E13: 1
B14: Ramal Simple 45º | C14: 110x110 MH | D14: Unidades | E14: 1
B15: Ramal Invertido | C15: 45º 50x50 | D15: Unidades | E15: 1
B16: Pileta de Patio | C16: 7 entr. 40x63 | D16: Unidades | E16: 1
B17: Tapa Macho | C17: 110mm | D17: Unidades | E17: 1
... B27: Rejilla Desague Ducha lineal 60 cm con filtro pelo tapa Acero Inox | C27: 40 bronce pulido | D27: Unidades | E27: 1
B28: Tarugos Fisher 8 | D28: Unidades | E28: 6
B29: Torinillos para tarugo 8 | D29: Unidades | E29: 6
B30: Agua
B31: Hidro3 Azul | C31: 1/2 | D31: Metros | E31: 4
B32: Hidro3 Azul | C32: 3/4 | D32: Metros | E32: 13.8
B33: Hidro3 Azul | C33: 1 | D33: Metros | E33: 23.97
B34: Hidro3 Azul | C34: 1 1/2 | D34: Metros | E34: 5
B35: Hidro3 Verde | C35: 1/2 | D35: Metros | E35: 2
B36: Hidro3 Verde | C36: 3/4 | D36: Metros | E36: 15.8
B37: Codo 90º F-F | C37: 1/2 | D37: Unidades | E37: 8
B38: Codo 90º F-F | C38: 1 | D38: Unidades | E38: 2
B39: Codo 90º F-F | C39: 1 1/2 | D39: Unidades | E39: 5
B40: Codo 90º F-F | C40: 2 | D40: Unidades | E40: 6
B41: Te F-F | C41: 1/2 | D41: Unidades | E41: 7
B42: Te F-F | C42: 1 1/2 | D42: Unidades | E42: 4
... B63: FV 430 13 B BCE CANILLA SERVICIO 1/2 | C63: 1/2 | D63: Unidades | E63: 3
B64: Flexible Mallado de 30 cm de largo | E64: 3
B65: Codo de bronce (M-M para virola 1/2" a 3/8") | E65: 2
B66: Tarugos Fisher 8 | E66: 6
B67: Torinillos bronce 22x70 | E67: 4
B68: Tornillo bronce 22x70 con conito plastico | E68: 2
B69: Portarejilla de Bronce y rejilla de 11x11 | E69: 1
B70: Sifon para pileta simple | E70: 1
B71: GAS
...

Sheet Materiales
D1: Cotizacion dolar BNA Venta | E1: 1550 | F1: 46295
D2: Cotizacion dolar Blue Venta | E2: 1550
D3: Completa
B5: Descripcion Tareas | C5: Un. | D5: Cantidad | E5: Precio Unitario | F5: Precio Parcial | G5: Procentaje | K5: % Gris
B6: Viga Fundacion con pilotines | C6: m3 | D6: 4.68 | E6: =+Aux!F25 -> 315615.69 | F6: =+E6*D6 -> 1477081.4 | G6: =+F6/$F$56 -> 0.017928426 | I6: =+F6 -> 1477081.4 | K6: =+I6/$I$56 -> 0.024756942
B7: Nylon incluye contrapiso perimetral se necesitan 115 m2 Rollo 100 m2 | C7: rollo | D7: 1.5 | E7: 33000 | F7: =+E7*D7 -> 49500 | G7: =+F7/$F$56 -> 0.00060081797 | I7: =+F7 -> 49500 | K7: =+I7/$I$56 -> 0.00082965543
B8: Contrapiso interior espesor 12 cm | C8: m2 | D8: =+Aux!A33 -> 62.7 | E8: =+Aux!E39 -> 104207.4 | F8: =+E8*D8 -> 6533804 | G8: =+F8/$F$56 -> 0.079305593 | I8: =+F8 -> 6533804 | K8: =+I8/$I$56 -> 0.10951123
B9: Carpeta de cemento 2 cm | C9: m2 | D9: =+Aux!A33 -> 62.7 | E9: =+Aux!E55 -> 12504.888 | F9: =+E9*D9 -> 784056.48 | G9: =+F9/$F$56 -> 0.0095166712 | I9: =+F9 -> 784056.48 | K9: =+I9/$I$56 -> 0.013141348
B10: Contrapiso Exterior espesor 12 cm | C10: m2 | D10: =+Aux!A49 -> 26 | E10: =+Aux!E55 -> 12504.888 | F10: =+E10*D10 -> 325127.09 | G10: =+F10/$F$56 -> 0.003946307 | I10: =+F10 -> 325127.09 | K10: =+I10/$I$56 -> 0.0054493627
B11: Carpeta de cemento | C11: m2 | D11: =+D10+D9 -> 88.7 | E11: =+Aux!E45 -> 3271.8956 | F11: =+E11*D11 -> 290217.14 | G11: =+F11/$F$56 -> 0.0035225792 | I11: =+F11 -> 290217.14 | K11: =+I11/$I$56 -> 0.0048642469
B12: MANTENIMIENTO DE OBRA | F12: =+E12*D12 -> 0 | G12: =+F12/$F$56 -> 0 | I12: =+F12 -> 0 | K12: =+I12/$I$56 -> 0
B13: Baño quimico mensual | C13: meses | D13: 3 | E13: 80000 | F13: =+E13*D13 -> 240000 | G13: =+F13/$F$56 -> 0.0029130568 | I13: =+F13 -> 240000 | K13: =+I13/$I$56 -> 0.0040225718
B14: Limpieza de obra periodica. Volquetes | C14: Volq | D14: 3 | E14: 140000 | F14: =+E14*D14 -> 420000 | G14: =+F14/$F$56 -> 0.0050978495 | I14: =+F14 -> 420000 | K14: =+I14/$I$56 -> 0.0070395006
B15: Obra Gris | F15: =+E15*D15 -> 0 | G15: =+F15/$F$56 -> 0 | I15: =+F15 -> 0 | K15: =+I15/$I$56 -> 0
B16: Paneles Kit Base OSB 11.1+EPS 15 kg/m3 | C16: gl | D16: 1 | E16: 26928566 | F16: =+E16*D16 -> 26928566 | G16: =+F16/$F$56 -> 0.32685185 | I16: =+F16 -> 26928566 | K16: =+I16/$I$56 -> 0.45134204
B17: Flete desde Cordoba | C17: gl | D17: 1 | E17: 800000 | F17: =+E17*D17 -> 800000 | G17: =+F17/$F$56 -> 0.0097101895 | I17: =+F17 -> 800000 | K17: =+I17/$I$56 -> 0.013408573
B18: Materiales de sellado adicionales paredes y techo | C18: gl | D18: 1 | E18: =+Aux!E66 -> 956000 | F18: =+E18*D18 -> 956000 | G18: =+F18/$F$56 -> 0.011603676 | I18: =+F18 -> 956000 | K18: =+I18/$I$56 -> 0.016023244
B19: Dinteles 3x4 | C19: ml | D19: =+Aux!D70 -> 15 | E19: =270000/27 -> 10000 | F19: =+E19*D19 -> 150000 | G19: =+F19/$F$56 -> 0.0018206605 | I19: =+F19 -> 150000 | K19: =+I19/$I$56 -> 0.0025141074
B20: Pergola quincho | C20: m2 | F20: =+E20*D20 -> 0 | G20: =+F20/$F$56 -> 0 | I20: =+F20 -> 0 | K20: =+I20/$I$56 -> 0
B21: Revestimiento placa de roca de yeso interior standard | C21: m2 | D21: =+PerimySup!F10 -> 137.5008 | E21: =+Aux!E83 -> 7272.7649 | F21: =+E21*D21 -> 1000011 | G21: =+F21/$F$56 -> 0.01213787 | J21: =+F21 -> 1000011 | K21: =+I21/$I$56 -> 0
B22: Revestimiento placa de roca de yeso interior RH | C22: m2 | D22: =+PerimySup!F11 -> 29.2 | E22: =+Aux!E90 -> 13106.619 | F22: =+E22*D22 -> 382713.28 | G22: =+F22/$F$56 -> 0.004645273 | J22: =+F22 -> 382713.28 | K22: =+I22/$I$56 -> 0
B23: Durlock Cielorraso Baño | C23: m2 | D23: 0 | F23: =+E23*D23 -> 0 | G23: =+F23/$F$56 -> 0 | I23: =+F23 -> 0 | K23: =+I23/$I$56 -> 0
B24: Revestimiento Exterior siding LP | C24: m2 | D24: =+Aux!B100 -> 136.9328 | E24: =+Aux!E104 -> 18055.04 | F24: =+E24*D24 -> 2472327.2 | G24: =+F24/$F$56 -> 0.030008457 | I24: =+F24 -> 2472327.2 | K24: =+I24/$I$56 -> 0.041437973
B25: Techos Chapa acanalado completo | C25: m2 | D25: =+Aux!E125 -> 78 | E25: =+Aux!E126 -> 45303.128 | F25: =+E25*D25 -> 3533644 | G25: =+F25/$F$56 -> 0.042890441 | I25: =+F25 -> 3533644 | K25: =+I25/$I$56 -> 0.059226402
B26: Canaletas | C26: ml | D26: =+Aux!B128 -> 12 | E26: 25000 | F26: =+E26*D26 -> 300000 | G26: =+F26/$F$56 -> 0.0036413211 | I26: =+F26 -> 300000 | K26: =+I26/$I$56 -> 0.0050282147
B27: Bajada de canaleta | C27: ml | D27: =+Aux!B129 -> 8 | E27: 25000 | F27: =+E27*D27 -> 200000 | G27: =+F27/$F$56 -> 0.0024275474 | I27: =+F27 -> 200000 | K27: =+I27/$I$56 -> 0.0033521431
B28: zingueria Carga | C28: ml | D28: =+Aux!B130 -> 30 | E28: 20000 | F28: =+E28*D28 -> 600000 | G28: =+F28/$F$56 -> 0.0072826421 | I28: =+F28 -> 600000 | K28: =+I28/$I$56 -> 0.010056429
B29: Botagua arranque panel SIP | C29: ml | D29: =+Aux!B131 -> 50 | E29: 15000 | F29: =+E29*D29 -> 750000 | G29: =+F29/$F$56 -> 0.0091033026 | I29: =+F29 -> 750000 | K29: =+I29/$I$56 -> 0.012570537
B30: Zingueria de dinteles | C30: ml | D30: =+Aux!B132 -> 13 | E30: 15000 | F30: =+E30*D30 -> 195000 | G30: =+F30/$F$56 -> 0.0023668587 | I30: =+F30 -> 195000 | K30: =+I30/$I$56 -> 0.0032683396
B31: INSTALACION SANITARIA | F31: =+E31*D31 -> 0 | G31: =+F31/$F$56 -> 0 | I31: =+F31 -> 0 | K31: =+I31/$I$56 -> 0
B32: Materiales Sanitarios | C32: gl | D32: 1 | E32: 850000 | F32: =+E32*D32 -> 850000 | G32: =+F32/$F$56 -> 0.010317076 | I32: =+F32*70% -> 595000 | J32: =+F32-I32 -> 255000 | K32: =+I32/$I$56 -> 0.0099726258
B33: Mano de Obra Sanitaria | C33: gl | D33: 1 | E33: =+E32 -> 850000 | F33: =+E33*D33 -> 850000 | G33: =+F33/$F$56 -> 0.010317076 | I33: =+F33*70% -> 595000 | J33: =+F33-I33 -> 255000 | K33: =+I33/$I$56 -> 0.0099726258
B34: Artefactos Sanitarios Gas segun listado | C34: gl | D34: 1 | E34: =+Aux!C147 -> 1172000 | F34: =+E34*D34 -> 1172000 | G34: =+F34/$F$56 -> 0.014225428 | J34: =+F34 -> 1172000 | K34: =+I34/$I$56 -> 0
B35: Extractores hidra 250 | C35: u | D35: 1 | E35: 32000 | F35: =+E35*D35 -> 32000 | G35: =+F35/$F$56 -> 0.00038840758 | I35: =+F35 -> 32000 | K35: =+I35/$I$56 -> 0.0005363429
B36: INSTALACION ELECTRICA | F36: =+E36*D36 -> 0 | G36: =+F36/$F$56 -> 0 | I36: =+F36 -> 0 | K36: =+I36/$I$56 -> 0
B37: Materiales electricos | C37: bocas | D37: 54 | E37: 60000 | F37: =+E37*D37 -> 3240000 | G37: =+F37/$F$56 -> 0.039326267 | I37: =+F37*70% -> 2268000 | J37: =+F37-I37 -> 972000 | K37: =+I37/$I$56 -> 0.038013303
B38: Mano de Obra Electrica | C38: =+C37 -> bocas | D38: =+D37 -> 54 | E38: =+E37 -> 60000 | F38: =+E38*D38 -> 3240000 | G38: =+F38/$F$56 -> 0.039326267 | I38: =+F38*70% -> 2268000 | J38: =+F38-I38 -> 972000 | K38: =+I38/$I$56 -> 0.038013303
B39: Puertas interiores marco madera | C39: u | D39: 3 | E39: 260000 | F39: =+E39*D39 -> 780000 | G39: =+F39/$F$56 -> 0.0094674347 | J39: =+F39 -> 780000 | K39: =+I39/$I$56 -> 0
B40: Puerta principal | C40: u | D40: 1 | E40: 1900000 | F40: =+E40*D40 -> 1900000 | G40: =+F40/$F$56 -> 0.0230617 | I40: =+F40 -> 1900000 | K40: =+I40/$I$56 -> 0.03184536
B41: Carpinteria de Alum con DVH | C41: gl | D41: 1 | E41: 5000000 | F41: =+E41*D41 -> 5000000 | G41: =+F41/$F$56 -> 0.060688684 | I41: =+F41 -> 5000000 | K41: =+I41/$I$56 -> 0.083803579
...

Sheet PerimySup
B1: PLANILLA DE PERIMETROS Y SUPERFICIES
C3: Perim | D3: Sup | E3: H prom | F3: Rev. Durlock SIP | G3: Imperm Ducha | H3: imp cielo | I3: piso | J3: revest. | K3: zocalo | L3: Siding Ext | M3: Pintura int. Muro | N3: Pintura int. Cielorr. | P3: bocas Ilum | Q3: tomas | R3: AA | S3: corr deb
B4: Estar com. Cocina paso | C4: 33.6 | D4: 39.5 | E4: 2.73 | I4: =+D4 -> 39.5 | J4: 4 | K4: =+C4 -> 33.6 | L4: =+(2.97+3.9+3.91+6.87)*3.5+14.41*2.8 -> 102.123 | M4: =+F4-J4 -> -4 | N4: =+D4 -> 39.5 | P4: 7 | Q4: 10 | R4: 1 | S4: 1 | U4: Estar com. Cocina paso
B5: Baño | C5: 8.5 | D5: 4.1 | E5: 2.89 | G5: =+(2+2)*E5 -> 11.56 | H5: =+D5 -> 4.1 | I5: =+D5 -> 4.1 | J5: =+E5*C5 -> 24.565 | M5: =+F5-J5 -> -24.565 | N5: =+D5 -> 4.1 | P5: 1 | Q5: 1 | U5: Baño
B6: Dormitorio | C6: 15.1 | D6: 12.9 | E6: 3.18 | I6: =+D6 -> 12.9 | K6: =+C6-2 -> 13.1 | M6: =+F6-J6 -> 0 | N6: =+D6 -> 12.9 | P6: 1 | Q6: 6 | R6: 1 | U6: Dormitorio
B7: Dormitorio | C7: 14.1 | D7: 11.5 | E7: 2.93 | I7: =+D7 -> 11.5 | K7: =+C7-2 -> 12.1 | M7: =+F7-J7 -> 0 | N7: =+D7 -> 11.5 | P7: 1 | Q7: 8 | R7: 1 | S7: 1 | U7: Escritorio
D8: =SUM(D4:D7) -> 68 | F8: =SUM(F4:F7) -> 0 | G8: =SUM(G5:G7) -> 11.56 | H8: =SUM(H5:H7) -> 4.1 | I8: =SUM(I4:I7) -> 68 | J8: =SUM(J4:J7) -> 28.565 | K8: =SUM(K4:K7) -> 58.8 | L8: =SUM(L4:L7) -> 102.123 | M8: =SUM(M4:M7) -> -28.565 | N8: =SUM(N4:N7) -> 68 | O8: Exterior | P8: 6 | Q8: 1
P9: =SUM(P4:P8) -> 16 | Q9: =SUM(Q4:Q8) -> 26 | R9: =SUM(R4:R8) -> 3 | S9: =SUM(S4:S8) -> 2 | T9: =SUM(P9:S9) -> 47
E10: Rev. Standar | F10: =46*2.44*1.22+10*2.44*1.22-F11 -> 137.5008 | Q10: 2 20 A
E11: Rev. RH | F11: 29.2 | Q11: 26 10 A
P12: Tomas 2 circ.
P13: Cajas rectangulares C1 | Q13: 12
P14: Cajas rectangulares C2 | Q14: 8 | T14: tomas de 10 A de uso general | U14: =6+12+8 -> 26
P15: Cano corrugado de 19-20 mm (3/4") | T15: tomas de 20 A de uso especial | U15: 2
O16: C1 | P16: 2x4 mm + N | Q16: =+Q17 -> 35 | R16: ml cada color | T16: Lavarropa | U16: 1
O17: C1 | P17: TM 20 A | Q17: 35 | R17: ml | T17: Aires de 2500 F | U17: 2
O18: C2 | P18: 2x2.5 mm + N | Q18: =2+4+3+3+2+5+6*0.3+1.5 -> 22.3 | T18: Aires de 3500 F | U18: 1
P19: bornera para 6 ramales capacidad 20 A | Q19: 1 | T19: Luminarias | U19: 22
O20: C2 | P20: TM 20 A | U20: =SUM(U14:U19) -> 54
J22: 550 | P22: Lavarropa
J23: 450 | P23: Cajas rectangulares | Q23: 2
P24: Cano corrugado de 19-20 mm (3/4") | Q24: 10
P25: 2x2.5 mm + N | Q25: =+Q24+1.5 -> 11.5
O26: C3 | P26: TM 20 A | Q26: 1
P28: Tomas 20A Cocina
P29: Cajas rectangulares | Q29: 6 | R29: u
P30: Cano corrugado de 19-20 mm (3/4") | Q30: 48.1 | R30: ml
P31: 2x2.5 mm + N | Q31: =+(Q32+Q33+Q35)*1.3 -> 18.2 | R31: ml cada color
O32: C4 cocina 2 tomas | P32: TM 20 A | Q32: 7 | S32: =1+1+2 -> 4 | T32: Técnicamente se puede (un circuito de 20A con dos tomas), pero no es lo reglamentario. La norma (AEA 90364-7-771) pide que cada toma de uso especial sea un circuito exclusivo, justamente porque están pensadas para artefactos de alto consumo que pueden funcionar de forma continua
O33: C5 cocina 4 tomas | P33: TM 10 A | Q33: 7
P35: Aire Acondicionado
P36: Cajas rectangulares | Q36: 3 | R36: u
P37: Cano corrugado de 19-20 mm (3/4") | Q37: =+Q38 -> 48.1
P38: 2x2.5 mm + N | Q38: =+(Q39+Q40+Q41)*1.3 -> 48.1 | R38: ml cada color
O39: C6 Dorm | P39: TM 10 A | Q39: =8+4 -> 12 | R39: ml
O40: C7 Estudio | P40: TM 10 A | Q40: =4+4 -> 8 | R40: ml
O41: C8 Living | P41: TM 16 A | Q41: =13+4 -> 17 | R41: ml | T41: 1
P43: Illuminacion 2 Ciruitos
P44: Cajas oct. 22 | Q44: 22 | R44: u
P45: Cano corrugado de 19-20 mm (3/4") | Q45: =+(Q47+Q48)*1.3 -> 55.9 | R45: ml
...

Sheet Aux
A3: Demolicion muros
A4: 0 | B4: ml
A5: 2.5 | B5: m altura
A6: 0.15 | B6: m espesor
A7: 1.5 | B7: esponjamiento
A8: =+A7*A6*A5*A4 -> 0 | B8: m3
A11: Vigas de Fundaciones 20x40
A12: Largos
A13: Medido en cad computo | B13: ml totales
A14: 4.68 | B14: m3
A16: Pilotines diam. 0.20 x 1.20 m
A17: 18 | B17: u
A18: =1.2*0.2*0.2 -> 0.048 | B18: m3
A19: =+A18*A17 -> 0.864 | B19: m3
A21: Hormigon Armado a mano 3x1 | B21: Cemento Avellaneda x 25 kg | C21: 357 | D21: kg | E21: 7722.72 | F21: =+E21*C21/25 -> 110280.44
A22: Hormigon Armado a mano 3x1 | B22: Arena en Bolsón | C22: 0.756 | D22: m3 | E22: 46405 | F22: =+E22*C22 -> 35082.18
A23: Hormigon Armado a mano 3x1 | B23: Piedra Partida | C23: 0.756 | D23: m3 | E23: 68460.35 | F23: =+E23*C23 -> 51756.025
A24: Hormigon Armado a mano 3x1 | B24: Hierro | C24: 60 | D24: kg | E24: 1974.9508 | F24: =+E24*C24 -> 118497.05
E25: Hormigon a mano | F25: =SUM(F21:F24) -> 315615.69 | G25: m3
A27: Contrapiso interior
A28: Sup. Parciales Contrapiso
A29: 37.3
A30: 3.5
A31: 11.7
A32: 10.2
A33: =SUM(A29:A32) -> 62.7 | B33: m2 interior
A34: Considero 12 cm | B34: =+A33*0.12 -> 7.524 | C34: m3
A35: Cemento Avellaneda x 25 kg | B35: 62.7 | C35: kg/m² | D35: 6625 | E35: =+D35*B35/25 -> 16615.5
A36: Arena en Bolsón | B36: 0.528 | C36: m3/m² | D36: 46405 | E36: =+D36*B36 -> 24501.84
A37: Cal Hidraulica x 20 kg | B37: 106.7 | C37: kg/m² | D37: 6100 | E37: =+D37*B37/20 -> 32543.5
A38: Cascote picado | B38: 0.88 | C38: m3/m² | D38: 34712 | E38: =+D38*B38 -> 30546.56
D39: Precio m3 | E39: =SUM(E35:E38) -> 104207.4
A41: Carpeta de cemento 2 cm
A42: Cemento Avellaneda x 25 kg | B42: 2.73 | C42: kg | D42: 6625 | E42: =+D42*B42/25 -> 723.45
A43: Arena en Bolsón | B43: 0.02331 | C43: m3 | D43: 46405 | E43: =+D43*B43 -> 1081.7006
A44: Cal Hidraulica x 20 kg | B44: 4.809 | C44: kg | D44: 6100 | E44: =+D44*B44/20 -> 1466.745
D45: Precio m2 | E45: =SUM(E42:E44) -> 3271.8956
A47: Contrapiso Exterior 12 cm
A48: incluye galeria trasera, lateral 0.50 m y recepcion ext en frente con escalon
A49: 26 | B49: m2 exterior
...

Sheet Consultas
B2: CONSULTAS y COMENTARIOS EN ROJO
B4: Descripcion Tareas | C4: Un.
B5: Demolicion Volquetes | C5: u | E5: cocina con porcelanato
B6: Viga Fundacion con pilotines | C6: m3 | E6: dormitorio simil madera
B7: Se calaran en contrapiso existente en correspondencia con muros SIP. | E7: escritorio carpeta cem para poner luego piso
B8: Nylon 200 micrones | C8: gl
B9: Contrapiso | C9: m2 | E9: alternativas de siding
B10: Reparacion existente | E10: chapa
B11: Carpeta de cemento | C11: m2 | E11: panel click insuma sur
B12: Completa nueva nivelando toda superficie | E12: horno anafe termo gas
B13: MANTENIMIENTO DE OBRA | E13: frio calor
B14: Baño quimico mensual | C14: meses | E14: biblioteca
B15: Limpieza de obra periodica. Volquetes | C15: Volq | E15: mesa ratona
B16: Obra Gris | E16: mesa tele
B17: Paneles Kit Base OSB 11.1+EPS 15 kg/m3 | C17: m2 | E17: cable router a internet
B18: Flete desde Cordoba | C18: gl | E18: martes miercoles
B19: Materiales de sellado adicionales paredes y techo | C19: gl
B20: Dinteles 3x6 | C20: ml
B21: Vigas pino celpillado de 3x8 o 3x10 de 7.30 m | C21: ml
B22: Para las vigas mas largas en zona Estar, el calculo de deformacion exigiria una viga de 10" la de 8" iria pero puede tener una leve deformacion que no implica ningun riesgo
B23: Durlock revestimiento interior | C23: m2
B24: Revestimiento Exterior siding LP o chapa | C24: m2
B25: Necesito su interes para revestimiento exterior
B26: Impermeabilizacion pintura poliuretanica locales humedos | C26: m2
B27: Techos Chapa acanalado completo | C27: m2
B28: eleccion del tipo de chapa (el mas comun ondulada), elegir color (la galvanizada es mas eficiente termicamente)
B29: Canaletas | C29: ml
B30: optar por canaleta o desague libre, pensar en hojas y su mantenimiento contra el inconveniente de tener un chorro de agua los dias de lluvia
B31: Bajada de canaleta | C31: ml
B32: zingueria Perimetral | C32: ml
B33: Botagua arranque panel SIP | C33: ml
B34: Zingueria de dinteles | C34: ml
B35: INSTALACION SANITARIA
B36: Materiales Sanitarios | C36: gl
B37: Termotanque Universal 60l Blanco | C37: gl
B38: Definir que va con gas, termotanque, cocina y como va a ser la calefaccion. Aire acondiciondo?
B39: Juego Baño Monaco Roca Inodoro Mochila Bidet Climb Hidromet | C39: Un.
B40: Propondremos una linea buena pero no costosa
B41: Inodoro con tapa | C41: u
B42: Vanitory completo
...
