Workbook

Sheet Computo
A1: CÓMPUTO SP_L80 - VIVIENDA MALDONADO (Ezeiza) - mismo aperturado que Aura
A2: Excluye carpinterías y muebles (según pedido). Precios en blanco para completar. Estado: MEDIDO (plano) / SIPCOR (ppto 2835) / ESTIMADO (verificar) / PENDIENTE (falta info).
A4: Descripción tareas | B4: Un. | C4: Cantidad | D4: Precio unit. | E4: Precio parcial | F4: Criterio / fuente | G4: Estado
A5: FUNDACIÓN Y CONTRAPISOS
A6: Platea H°A s/ cálculo (cubierta + semicubierta) | B6: m² | C6: =145.87+63.55 -> 209.42 | E6: =C6*D6 -> 0 | F6: Plano: detalle platea / estructura en platea (cálculo estructural pendiente). Cub+semi s/ balance | G6: ESTIMADO
A7: Nylon bajo platea / contrapisos (rollo 100 m²) | B7: rollo | C7: =ROUNDUP(C6*1.1/100,0) -> 3 | E7: =C7*D7 -> 0 | F7: Sup platea +10% solape | G7: ESTIMADO
A8: Carpeta de cemento 2 cm interior | B8: m² | C8: =Locales!J15 -> 119.29 | E8: =C8*D8 -> 0 | F8: Σ pisos interiores | G8: MEDIDO
A9: Contrapiso exterior esp. 12 cm (galería+cochera+deck) | B9: m² | C9: =Locales!E19+Locales!E20+Locales!E21 -> 80.02 | E9: =C9*D9 -> 0 | F9: Confirmar si galería/cochera van sobre platea (plano 10) | G9: ESTIMADO
A10: Carpeta de cemento exterior | B10: m² | C10: =C9 -> 80.02 | E10: =C10*D10 -> 0 | F10: Igual a contrapiso exterior | G10: ESTIMADO
A11: MANTENIMIENTO DE OBRA
A12: Baño químico mensual | B12: meses | C12: 4 | E12: =C12*D12 -> 0 | F12: Ref. Aura 3 meses p/ 73 m²; plazo a definir | G12: PENDIENTE
A13: Limpieza periódica. Volquetes | B13: Volq | C13: 4 | E13: =C13*D13 -> 0 | F13: Ref. Aura 3; a definir | G13: PENDIENTE
A14: OBRA GRIS
A15: Paneles Kit Full SIPCOR (OSB 11,1 + EPS 15 kg/m³) | B15: gl | C15: 1 | E15: =C15*D15 -> 0 | F15: SIPCOR ppto 2835 16/09/26: USD 33.850,50 + IVA 21% = USD 40.959,11 (ver hoja Ref_SIPCOR) | G15: SIPCOR
A16: Flete desde Córdoba | B16: gl | C16: 1 | E16: =C16*D16 -> 0 | F16: No incluido en SIPCOR; cotizar a Ezeiza | G16: PENDIENTE
A17: Materiales de sellado adicionales paredes y techo | B17: gl | C17: 1 | E17: =C17*D17 -> 0 | F17: Ref. Aura (gl); ajustar por m² de panel | G17: PENDIENTE
A18: Tirantes de techo, vigas y dinteles (madera) - NO incluidos en SIPCOR | B18: gl | C18: 1 | E18: =C18*D18 -> 0 | F18: SIPCOR aclara que no los incluye. Ver manual de instalación | G18: PENDIENTE
A19: Dinteles 3x4 | B19: ml | C19: 28 | E19: =C19*D19 -> 0 | F19: Σ anchos de aberturas estimados del plano (ilum. proy.). Verificar con planilla aberturas | G19: ESTIMADO
A20: Revestimiento placa de roca interior estándar | B20: m² | C20: =Locales!H15 -> 222.404 | E20: =C20*D20 -> 0 | F20: Perím×H locales secos, sin descontar vanos (criterio Aura) | G20: MEDIDO
A21: Revestimiento placa de roca interior RH | B21: m² | C21: =Locales!I15 -> 74.88 | E21: =C21*D21 -> 0 | F21: Baños y lavadero, perím×H | G21: MEDIDO
A22: Durlock cielorraso baño | B22: m² | C22: 0 | E22: =C22*D22 -> 0 | F22: Cielorraso = panel techo SIP50 MDF ranurado (SIPCOR); sin durlock | G22: MEDIDO
A23: Revestimiento exterior (siding LP / Tarquini gris s/ plano) | B23: m² | C23: =64*1.22*2.44 -> 190.5152 | E23: =C23*D23 -> 0 | F23: 64 muros ext. SIPCOR × 1,22×2,44 (no descuenta vanos). No incluye hastiales. Plano indica "Tarquini gris": definir terminación | G23: SIPCOR
A24: Cubierta de techo (teja / chapa a definir) sobre paneles | B24: m² | C24: =137*0.6*2.4 -> 197.28 | E24: =C24*D24 -> 0 | F24: 137 paneles techo SIP50 0,60×2,40 (SIPCOR). Plano: techo tipo teja | G24: SIPCOR
A25: Techo semicubierta (galería+cochera): estructura madera y cubierta | B25: m² | C25: =63.55 -> 63.55 | E25: =C25*D25 -> 0 | F25: Balance plano (proyección horizontal). Fuera del kit SIPCOR | G25: ESTIMADO
A26: Canaletas | B26: ml | C26: 30 | E26: =C26*D26 -> 0 | F26: Estimado aleros principales (2×14,65). Verificar planta de techos 13 | G26: ESTIMADO
A27: Bajada de canaleta | B27: ml | C27: 10.4 | E27: =C27*D27 -> 0 | F27: 4 bajadas × 2,6 m | G27: ESTIMADO
A28: Zinguería de carga | B28: ml | C28: =ROUND(C29*30/50,1) -> 46.8 | E28: =C28*D28 -> 0 | F28: Ratio Aura (30 ml / 50 ml perím.) × perím. panel ext. | G28: ESTIMADO
A29: Botagua arranque panel SIP | B29: ml | C29: =64*1.22 -> 78.08 | E29: =C29*D29 -> 0 | F29: Perímetro base muros ext. (64 paneles × 1,22) | G29: SIPCOR
A30: Zinguería de dinteles | B30: ml | C30: =C19 -> 28 | E30: =C30*D30 -> 0 | F30: Igual a dinteles | G30: ESTIMADO
A31: INSTALACIÓN SANITARIA
A32: Materiales sanitarios | B32: gl | C32: 1 | E32: =C32*D32 -> 0 | F32: 2 baños + toilette + lavadero + cocina. Ver plano "Instalación sanitaria PB" | G32: PENDIENTE
A33: Mano de obra sanitaria | B33: gl | C33: 1 | E33: =C33*D33 -> 0 | F33: idem | G33: PENDIENTE
A34: Artefactos sanitarios (juego baño ×2, inodoro toilette, pileta lavadero doble, bacha cocina) | B34: gl | C34: 1 | E34: =C34*D34 -> 0 | F34: Listado a definir | G34: PENDIENTE
A35: Extractores | B35: u | C35: 3 | E35: =C35*D35 -> 0 | F35: Toilette, lavadero y depósito sin ventilación (Art. 4.6.5.1) | G35: ESTIMADO
A36: Tanque cisterna enterrado 1500 l | B36: u | C36: 1 | E36: =C36*D36 -> 0 | F36: Indicado en plano | G36: MEDIDO
A37: INSTALACIÓN ELÉCTRICA
A38: Materiales eléctricos | B38: bocas | C38: =ROUND(0.79*145.87,0) -> 115 | E38: =C38*D38 -> 0 | F38: Ratio Aura 0,79 bocas/m² × sup cubierta. Sin proyecto eléctrico | G38: ESTIMADO
A39: Mano de obra eléctrica | B39: bocas | C39: =C38 -> 115 | E39: =C39*D39 -> 0 | F39: idem | G39: ESTIMADO
A40: TERMINACIONES
A41: Piso porcelanato interior | B41: m² | C41: =Locales!J15 -> 119.29 | E41: =C41*D41 -> 0 | F41: Σ pisos interiores (living 60×60 blanco; resto a definir) | G41: MEDIDO
...

Sheet Locales
A1: PLANILLA DE LOCALES - PERÍMETROS Y SUPERFICIES (SP_L80 - Maldonado, Ezeiza)
A2: Azul = dato de entrada (editable). Superficies de la Tabla de Iluminación del plano; perímetros por cotas del plano (irregulares = estimados, verificar en CAD). H = altura de cálculo de muros (nivel +2,59 del plano).
A3: Altura H de cálculo (m): | C3: 2.6
A5: N° | B5: Local | C5: Tipo | D5: Perím (m) | E5: Sup (m²) | F5: H (m) | G5: Perím×H (m²) | H5: Durlock STD (m²) | I5: Durlock RH (m²) | J5: Piso interior (m²) | K5: Revest. cerám. (m²) | L5: Zócalo (ml) | M5: Imperm. ducha (m²) | N5: Fuente / criterio | O5: Estado
A6: 01 | B6: Dormitorio 1 (incl. vestidor) | C6: Interior | D6: 18.64 | E6: 20.27 | F6: =$C$3 -> 2.6 | G6: =D6*F6 -> 48.464 | H6: =G6 -> 48.464 | I6: 0 | J6: =E6 -> 20.27 | K6: 0 | L6: =D6 -> 18.64 | M6: 0 | N6: Sup tabla plano. Perím = rect. 3,46×5,86 equiv. (incluye vestidores 0,60/0.98/0,60) | O6: ESTIMADO
A7: 02 | B7: Baño (toilette) | C7: Interior | D7: 5.26 | E7: 1.6 | F7: =$C$3 -> 2.6 | G7: =D7*F7 -> 13.676 | H7: 0 | I7: =G7 -> 13.676 | J7: =E7 -> 1.6 | K7: =G7 -> 13.676 | L7: 0 | M7: 0 | N7: Sup tabla. Perím 0,96×1,67 | O7: MEDIDO
A8: 03 | B8: Depósito | C8: Interior | D8: 8.74 | E8: 2.6 | F8: =$C$3 -> 2.6 | G8: =D8*F8 -> 22.724 | H8: =G8 -> 22.724 | I8: 0 | J8: =E8 -> 2.6 | K8: 0 | L8: 0 | M8: 0 | N8: Sup tabla. Perím 0,74×3,63 cotas | O8: MEDIDO
A9: 04 | B9: Lavadero | C9: Interior | D9: 8.54 | E9: 4.33 | F9: =$C$3 -> 2.6 | G9: =D9*F9 -> 22.204 | H9: 0 | I9: =G9 -> 22.204 | J9: =E9 -> 4.33 | K9: 0 | L9: 0 | M9: 0 | N9: Sup tabla. Perím 1,71×2,56 cotas | O9: MEDIDO
A10: 05 | B10: Cocina - Living - Comedor | C10: Interior | D10: 31.4 | E10: 61.17 | F10: =$C$3 -> 2.6 | G10: =D10*F10 -> 81.64 | H10: =G10 -> 81.64 | I10: 0 | J10: =E10 -> 61.17 | K10: 0 | L10: =D10 -> 31.4 | M10: 0 | N10: Sup tabla. Local irregular (7,43×6,00 + hall): perím equiv. rect. 8,40×7,28 | O10: ESTIMADO
A11: 06 | B11: Baño 1 | C11: Interior | D11: 7.5 | E11: 3.5 | F11: =$C$3 -> 2.6 | G11: =D11*F11 -> 19.5 | H11: 0 | I11: =G11 -> 19.5 | J11: =E11 -> 3.5 | K11: =G11 -> 19.5 | L11: 0 | M11: 11.56 | N11: 1,99×1,76 cotas | O11: MEDIDO
A12: 07 | B12: Baño 2 | C12: Interior | D12: 7.5 | E12: 3.5 | F12: =$C$3 -> 2.6 | G12: =D12*F12 -> 19.5 | H12: 0 | I12: =G12 -> 19.5 | J12: =E12 -> 3.5 | K12: =G12 -> 19.5 | L12: 0 | M12: 11.56 | N12: 1,99×1,76 cotas | O12: MEDIDO
A13: 08 | B13: Dormitorio 2 | C13: Interior | D13: 13.38 | E13: 11.16 | F13: =$C$3 -> 2.6 | G13: =D13*F13 -> 34.788 | H13: =G13 -> 34.788 | I13: 0 | J13: =E13 -> 11.16 | K13: 0 | L13: =D13 -> 13.38 | M13: 0 | N13: 3,20×3,49 (sup tabla incl. placard 0,60) | O13: MEDIDO
A14: 09 | B14: Dormitorio 3 | C14: Interior | D14: 13.38 | E14: 11.16 | F14: =$C$3 -> 2.6 | G14: =D14*F14 -> 34.788 | H14: =G14 -> 34.788 | I14: 0 | J14: =E14 -> 11.16 | K14: 0 | L14: =D14 -> 13.38 | M14: 0 | N14: 3,20×3,49 (sup tabla incl. placard 0,60) | O14: MEDIDO
B15: TOTAL INTERIORES | D15: =SUM(D6:D14) -> 114.34 | E15: =SUM(E6:E14) -> 119.29 | G15: =SUM(G6:G14) -> 297.284 | H15: =SUM(H6:H14) -> 222.404 | I15: =SUM(I6:I14) -> 74.88 | J15: =SUM(J6:J14) -> 119.29 | K15: =SUM(K6:K14) -> 52.676 | L15: =SUM(L6:L14) -> 76.8 | M15: =SUM(M6:M14) -> 23.12
B17: SEMICUBIERTAS Y PISOS EXTERIORES
A18: N° | B18: Local / Zona | C18: Tipo | D18: Perím (m) | E18: Sup (m²) | N18: Fuente / criterio | O18: Estado
A19: 10 | B19: Galería | C19: Semicubierta | D19: 21.5 | E19: 26.22 | N19: 7,01×3,74 (cotas plano). Piso porcelanato 40×40 gris claro | O19: MEDIDO
A20: 11 | B20: Cochera | C20: Semicubierta | D20: 23.62 | E20: 34.55 | N20: 6,47×5,34 (cotas plano). Piso porcelanato 40×40 gris claro | O20: MEDIDO
A21: 12 | B21: Deck pileta (baldosa refractaria antideslizante) | C21: Exterior | D21: 29 | E21: 19.25 | N21: Deck 10,50×4,50 = 47,25 − espejo pileta 28,00. Cotas plano | O21: MEDIDO
A22: 13 | B22: Pileta de natación (espejo) | C22: Exterior | D22: 23 | E22: 28 | N22: 8,00×3,50 (balance de superficies plano). Estructura H°A | O22: MEDIDO
B24: CONTROL DE SUPERFICIES
B25: Σ locales interiores (m²) | E25: =E15 -> 119.29
B26: Cubierta s/ plano - balance (m²) | E26: 145.87
B27: Diferencia = tabiques, muros, circulaciones no listados (m²) | E27: =E26-E25 -> 26.58
B28: Semicubierta s/ plano - balance (m²) | E28: 63.55
B29: Σ galería+cochera medidas (m²) | E29: =E19+E20 -> 60.77
B30: Total s/ plano (cub+semi) (m²) | E30: =E26+E28 -> 209.42
B31: Superficie cubierta SIPCOR (ppto 2835) (m²) | E31: 140.3
B32: Semicubierta SIPCOR (m²) | E32: 23.7
B33: ALERTA: semicubierta plano vs SIPCOR (m²) | E33: =E28-E32 -> 39.85

Sheet Ref_SIPCOR
A1: REFERENCIA - PRESUPUESTO SIPCOR Nº 2835 (16/09/2026) - Diego Maldonado, Ezeiza
A3: Ubic. | B3: Descripción | C3: Cant. (u) | D3: Medida unit. | E3: Ml total | F3: m² total | G3: USD unit. | H3: USD total
A4: Muro | B4: Muro SIP70 Exterior - kit con insumos (1,22×2,44×0,092; OSB 11,1; EPS 15) | C4: 64 | D4: 1,22×2,44 | E4: =C4*1.22 -> 78.08 | F4: =C4*1.22*2.44 -> 190.5152 | G4: 191.97 | H4: 12286.08
A5: Muro | B5: Muro SIP70 Interior - kit con insumos | C5: 56 | D5: 1,22×2,44 | E5: =C5*1.22 -> 68.32 | F5: =C5*1.22*2.44 -> 166.7008 | G5: 173.86 | H5: 9736.16
A6: Esquina | B6: Esquina SIP70 con insumos (2,44 ml) | C6: 46 | D6: 2,44 ml | E6: =C6*2.44 -> 112.24 | G6: 14.91 | H6: 685.86
A7: Entrepiso | B7: Entrepiso SIP70 con insumos (altillo) | C7: 13 | D7: 1,22×2,44 | E7: =C7*1.22 -> 15.86 | F7: =C7*1.22*2.44 -> 38.6984 | G7: 149.45 | H7: 1942.85
A8: Techo | B8: Techo SIP50 ranurado MDF (0,60×2,40×0,0685) | C8: 137 | D8: 0,60×2,40 | F8: =C8*0.6*2.4 -> 197.28 | G8: 67.15 | H8: 9199.55
G10: Subtotal | H10: =SUM(H4:H8) -> 33850.5
G11: IVA 21% | H11: =H10*0.21 -> 7108.605
G12: TOTAL USD | H12: =H10+H11 -> 40959.105
G13: TC 15/9/26 | H13: 1530
G14: TOTAL $ | H14: =H12*H13 -> 62667431
A16: Notas
A17: SIPCOR superficie de obra: cubierta 140,30 + semicubierta 23,70 = 164,00 m². El plano municipal indica 145,87 + 63,55 = 209,42 m² (la semicubierta difiere 39,85 m²: galería/cochera en madera quedarían fuera del kit).
A18: No incluye: flete (entrega en Corral de Bustos, Córdoba), tirantes de techo, vigas ni dinteles. Validez 5 días con ajuste dólar BNA.
A19: Muros: 64 ext. = 78,08 ml; 56 int. = 68,32 ml. Se usaron para siding (m²), botagua (ml) y control de perímetros.
A20: El presupuesto SIPCOR es inicial; la cantidad de paneles puede variar con la modulación y los manuales de corte.

Sheet Supuestos
A1: SUPUESTOS Y PENDIENTES A VERIFICAR
A3: 1. Plano municipal de una sola planta (PB, NPT 0,00; nivel +2,59; cumbrera hasta +5,23/+5,35). Altura de cálculo H=2,60 m (celda Locales!C3, editable; los hastiales del living elevan el promedio real).
A4: 2. Perímetros de locales 01 y 05 son equivalentes rectangulares (locales irregulares). Verificar en CAD; impacta durlock, látex y zócalo.
A5: 3. Siding exterior: a partir de paneles SIPCOR (64 muros ext. × 2,44 m). Falta hastiales y terminación "Tarquini gris" que indica el plano.
A6: 4. Techo: 197,28 m² de paneles SIPCOR (137 × 1,44). Cubierta teja vs chapa, y tirantes, no definidos / no incluidos.
A7: 5. Eléctrica, sanitaria, canaletas, dinteles, mantenimiento y vereda son estimaciones por ratio Aura o criterio; no hay proyecto de instalaciones cuantificable.
A8: 6. Excluidos por pedido: carpinterías (aberturas, puertas) y muebles (cocina, mesadas, placards).
A9: 7. Altillo ("Acceso altillo" en plano) tiene 13 paneles de entrepiso SIPCOR; no hay datos de escalera/terminación.
A10: 8. Para cargar precios usar la columna D de Computo (precio parcial y total se calculan solos).
